Workbook

Sheet Dashboard
A1: 📊 DASHBOARD
B4: ⚡ AGENT BALANCE
B5: Current Agent Balance (USD) | E5: =IFERROR(LOOKUP(2,1/(Transactions!$K$5:$K$300<>""),Transactions!$K$5:$K$300),Settings!$C$4) -> 4329979.8
B6: Starting Balance | E6: =Settings!$C$4 -> 0
B8: 📋 INVOICES
B9: Invoices Submitted — total count | E9: =COUNTA(Invoices!$A$5:$A$200) -> 40
B10: ✅ Paid — count | E10: =COUNTIF(Invoices!$G$5:$G$200,"✅ Paid") -> 29
B11: ✅ Paid — USD total (approx) | E11: =SUMIF(Invoices!$G$5:$G$200,"✅ Paid",Invoices!$F$5:$F$200) -> 1921335.9
B12: ⏳ Pending — count | E12: =COUNTIF(Invoices!$G$5:$G$200,"⏳ Pending") -> 11
B13: ⏳ Pending — USD total (known amounts) | E13: =SUMIF(Invoices!$G$5:$G$200,"⏳ Pending",Invoices!$F$5:$F$200) -> 382101.19
B14: ❓ Clarify / ⚠ Check — count | E14: =COUNTIF(Invoices!$G$5:$G$200,"❓ Clarify")+COUNTIF(Invoices!$G$5:$G$200,"⚠ Partial/Check") -> 0
B15: 📊 Total Unpaid — all statuses (USD equiv, projected) | E15: =SUMPRODUCT(IF(Invoices!$G$5:$G$200<>"✅ Paid",IF(Invoices!$G$5:$G$200<>"",IF(ISNUMBER(Invoices!$F$5:$F$200),Invoices!$F$5:$F$200,0),0),0)) -> 382101.19
B17: 💸 TRANSACTIONS SUMMARY
B18: Total Deposits to Agent (Gross USD) | E18: =SUMIF(Transactions!$B$5:$B$300,"Deposit",Transactions!$H$5:$H$300) -> 27843225
B19: Total Cash Received from Agent (Gross USD) | E19: =SUMIF(Transactions!$B$5:$B$300,"Cash Out",Transactions!$H$5:$H$300) -> 3590783.2
B20: Total Payments Made (Gross USD) | E20: =SUMIF(Transactions!$B$5:$B$300,"Payment",Transactions!$H$5:$H$300) -> 20047019
B21: ❓ Unknown — needs clarification (USD) | E21: =SUMIF(Transactions!$B$5:$B$300,"❓ Unknown",Transactions!$H$5:$H$300) -> 0

Sheet Transactions
A1: 💳 TRANSACTIONS
A2: Columns G–K are formulas (yellow) — only fill A–F and L. Override G or I if agent used a different rate.
A4: Date | B4: Type | C4: Description | D4: Payee | E4: CCY | F4: Amount | G4: FX Rate (1 USD=X) | H4: Gross USD | I4: Comm % | J4: Net USD | K4: Balance USD | L4: Notes
A5: ~Dec 2025 | B5: Deposit | C5: 50M AED deposit to agent | D5: (us) | E5: AED | F5: 50000000 | G5: 3.6725 | H5: 13614704 | I5: 0 | J5: 13614704 | K5: 13614704 | L5: Opening deposit. Agent confirms $13,614,703.88 in 25.12 balance stmt
A6: 22.12.2025 | B6: Payment | C6: Chem Ron hire SH-TC2401-22 → Polaris Marine | D6: POLARIS MARINE LIMITED | E6: CNY | F6: 74520 | G6: 7.038 | H6: 10588.24 | I6: 0.005 | J6: -10641.45 | K6: 13604062 | L6: Jiaren Marine / PING AN Bank. 25.12 balance confirmed
A7: 25.12.2025 | B7: Payment | C7: RUB payment — prior deal (ЦБ 78.4368) | D7: TRADE X MIDDLE EAST FZCO | E7: RUB | F7: 1.0627909e+09 | G7: 78.4368 | H7: 13549646 | I7: 0.004 | J7: -13604062 | K7: 0.23 | L7: Balance = $0 after this. 25.12 balance stmt
A8: ~Late Dec | B8: Deposit | C8: CNY 79,993,251 — Nexus → Elitesphere PingAn | D8: (us) | E8: CNY | F8: 79993251 | G8: 7.01251 | H8: 11407218 | I8: 0 | J8: 11407218 | K8: 11407218 | L8: RCVD confirmed 30.12.2025
A9: 29.12.2025 | B9: Payment | C9: Jiangsu Jinyangtong Shipping (Solhut Intercontinental) | D9: JIANGSU JINYANGTONG SHIPPING | E9: CNY | F9: 381089 | G9: 7.01251 | H9: 54344.15 | I9: 0.005 | J9: -54617.24 | K9: 11352601 | L9: Solhut HK. BofChina. Ref PI9HK3587KA01546
A10: 06.01.2026 | B10: Payment | C10: Chem Ron 23rd hire SH-TC2401-23 → Polaris Marine | D10: POLARIS MARINE LIMITED | E10: CNY | F10: 4356737 | G10: 7.01251 | H10: 621280.51 | I10: 0.005 | J10: -624402.52 | K10: 10728198 | L10: Bank of Shanghai → PingAn. USD 696k equiv
A11: 07.01.2026 | B11: Cash Out | C11: Cash 2,000,000 AED → Wladimir | D11: (us) | E11: AED | F11: 2000000 | G11: 3.6725 | H11: 544588.16 | I11: 0.005 | J11: -547324.78 | K11: 10180873 | L11: Hoja delivered. Wladimir confirmed
A12: 08.01.2026 | B12: Cash Out | C12: Cash 1,650,000 AED → Alex | D12: (us) | E12: AED | F12: 1650000 | G12: 3.6725 | H12: 449285.23 | I12: 0.005 | J12: -451542.94 | K12: 9729330.4 | L12: Hoja delivered. Alex confirmed
A13: 14.01.2026 | B13: Payment | C13: RUB → Trade X (=$5M USD equiv, ЦБ 78.8527) | D13: TRADE X MIDDLE EAST FZCO | E13: RUB | F13: 392686446 | G13: 78.8527 | H13: 4980000 | I13: 0.004 | J13: -5000000 | K13: 4729330.5 | L13: Masadan Trading payer. ИСПОЛНЕНО 14.01.2026
A14: 14.01.2026 | B14: Cash Out | C14: Cash 3,000,000 AED → office | D14: (us) | E14: AED | F14: 3000000 | G14: 3.6725 | H14: 816882.23 | I14: 0.005 | J14: -820987.17 | K14: 3908343.3 | L14: Delivered to office. Wladimir/Alex received
A15: 14.01.2026 | B15: Payment | C15: Al Watan RAK — inv 2000166506 | D15: AL WATAN RAK | E15: AED | F15: 30240 | G15: 3.6725 | H15: 8234.17 | I15: 0.005 | J15: -8275.55 | K15: 3900067.7 | L15: Inv date 31.12.2025. RAWRIMA payer. Ref 1164015
A16: 14.01.2026 | B16: Payment | C16: Lux Lifestyles — LUX-INV2025-228 | D16: LUX LIFESTYLES TRADING LLC | E16: AED | F16: 1890 | G16: 3.6725 | H16: 514.64 | I16: 0.005 | J16: -517.23 | K16: 3899550.5 | L16: Event support 01.12.2025. RAWRIMA payer. Ref 1163835
... A43: 25.02.2026 | B43: Payment | C43: INV 4410 — 5YZ W L L-2 (invoice 1,980 BHD, paid in AED) | D43: 5YZ W L L-2 | E43: AED | F43: 19502.1 | G43: 3.6725 | H43: 5310.31 | I43: 0.005 | J43: -5336.99 | K43: 4329979.8 | L43: Original invoice in 1,980 BHD. Agent paid in AED. SWIFT confirmed.
G44: =IF(E46="","",IFERROR(VLOOKUP(E46,Settings!$A$7:$B$17,2,FALSE()),1)) | H44: =IF(OR(F46="",G46=""),"",F46/G46) | I44: =IF(B46="","",IFERROR(VLOOKUP(B46,Settings!$E$19:$F$23,2,FALSE()),0)) | J44: =IF(H46="","",IF(OR(B46="Deposit",B46="Cash In"),H46,-(H46/MAX(1-I46,0.0001)))) | K44: =IF(J46="","",IF(ISNUMBER(K45),K45,Settings!$C$4)+J46)
G45: =IF(E47="","",IFERROR(VLOOKUP(E47,Settings!$A$7:$B$17,2,FALSE()),1)) | H45: =IF(OR(F47="",G47=""),"",F47/G47) | I45: =IF(B47="","",IFERROR(VLOOKUP(B47,Settings!$E$19:$F$23,2,FALSE()),0)) | J45: =IF(H47="","",IF(OR(B47="Deposit",B47="Cash In"),H47,-(H47/MAX(1-I47,0.0001)))) | K45: =IF(J47="","",IF(ISNUMBER(K46),K46,Settings!$C$4)+J47)
G46: =IF(E48="","",IFERROR(VLOOKUP(E48,Settings!$A$7:$B$17,2,FALSE()),1)) | H46: =IF(OR(F48="",G48=""),"",F48/G48) | I46: =IF(B48="","",IFERROR(VLOOKUP(B48,Settings!$E$19:$F$23,2,FALSE()),0)) | J46: =IF(H48="","",IF(OR(B48="Deposit",B48="Cash In"),H48,-(H48/MAX(1-I48,0.0001)))) | K46: =IF(J48="","",IF(ISNUMBER(K47),K47,Settings!$C$4)+J48)
G47: =IF(E49="","",IFERROR(VLOOKUP(E49,Settings!$A$7:$B$17,2,FALSE()),1)) | H47: =IF(OR(F49="",G49=""),"",F49/G49) | I47: =IF(B49="","",IFERROR(VLOOKUP(B49,Settings!$E$19:$F$23,2,FALSE()),0)) | J47: =IF(H49="","",IF(OR(B49="Deposit",B49="Cash In"),H49,-(H49/MAX(1-I49,0.0001)))) | K47: =IF(J49="","",IF(ISNUMBER(K48),K48,Settings!$C$4)+J49)
G48: =IF(E50="","",IFERROR(VLOOKUP(E50,Settings!$A$7:$B$17,2,FALSE()),1)) | H48: =IF(OR(F50="",G50=""),"",F50/G50) | I48: =IF(B50="","",IFERROR(VLOOKUP(B50,Settings!$E$19:$F$23,2,FALSE()),0)) | J48: =IF(H50="","",IF(OR(B50="Deposit",B50="Cash In"),H50,-(H50/MAX(1-I50,0.0001)))) | K48: =IF(J50="","",IF(ISNUMBER(K49),K49,Settings!$C$4)+J50)
G49: =IF(E51="","",IFERROR(VLOOKUP(E51,Settings!$A$7:$B$17,2,FALSE()),1)) | H49: =IF(OR(F51="",G51=""),"",F51/G51) | I49: =IF(B51="","",IFERROR(VLOOKUP(B51,Settings!$E$19:$F$23,2,FALSE()),0)) | J49: =IF(H51="","",IF(OR(B51="Deposit",B51="Cash In"),H51,-(H51/MAX(1-I51,0.0001)))) | K49: =IF(J51="","",IF(ISNUMBER(K50),K50,Settings!$C$4)+J51)
G50: =IF(E52="","",IFERROR(VLOOKUP(E52,Settings!$A$7:$B$17,2,FALSE()),1)) | H50: =IF(OR(F52="",G52=""),"",F52/G52) | I50: =IF(B52="","",IFERROR(VLOOKUP(B52,Settings!$E$19:$F$23,2,FALSE()),0)) | J50: =IF(H52="","",IF(OR(B52="Deposit",B52="Cash In"),H52,-(H52/MAX(1-I52,0.0001)))) | K50: =IF(J52="","",IF(ISNUMBER(K51),K51,Settings!$C$4)+J52)
G51: =IF(E53="","",IFERROR(VLOOKUP(E53,Settings!$A$7:$B$17,2,FALSE()),1)) | H51: =IF(OR(F53="",G53=""),"",F53/G53) | I51: =IF(B53="","",IFERROR(VLOOKUP(B53,Settings!$E$19:$F$23,2,FALSE()),0)) | J51: =IF(H53="","",IF(OR(B53="Deposit",B53="Cash In"),H53,-(H53/MAX(1-I53,0.0001)))) | K51: =IF(J53="","",IF(ISNUMBER(K52),K52,Settings!$C$4)+J53)
G52: =IF(E54="","",IFERROR(VLOOKUP(E54,Settings!$A$7:$B$17,2,FALSE()),1)) | H52: =IF(OR(F54="",G54=""),"",F54/G54) | I52: =IF(B54="","",IFERROR(VLOOKUP(B54,Settings!$E$19:$F$23,2,FALSE()),0)) | J52: =IF(H54="","",IF(OR(B54="Deposit",B54="Cash In"),H54,-(H54/MAX(1-I54,0.0001)))) | K52: =IF(J54="","",IF(ISNUMBER(K53),K53,Settings!$C$4)+J54)
G53: =IF(E55="","",IFERROR(VLOOKUP(E55,Settings!$A$7:$B$17,2,FALSE()),1)) | H53: =IF(OR(F55="",G55=""),"",F55/G55) | I53: =IF(B55="","",IFERROR(VLOOKUP(B55,Settings!$E$19:$F$23,2,FALSE()),0)) | J53: =IF(H55="","",IF(OR(B55="Deposit",B55="Cash In"),H55,-(H55/MAX(1-I55,0.0001)))) | K53: =IF(J55="","",IF(ISNUMBER(K54),K54,Settings!$C$4)+J55)
G54: =IF(E56="","",IFERROR(VLOOKUP(E56,Settings!$A$7:$B$17,2,FALSE()),1)) | H54: =IF(OR(F56="",G56=""),"",F56/G56) | I54: =IF(B56="","",IFERROR(VLOOKUP(B56,Settings!$E$19:$F$23,2,FALSE()),0)) | J54: =IF(H56="","",IF(OR(B56="Deposit",B56="Cash In"),H56,-(H56/MAX(1-I56,0.0001)))) | K54: =IF(J56="","",IF(ISNUMBER(K55),K55,Settings!$C$4)+J56)
G55: =IF(E57="","",IFERROR(VLOOKUP(E57,Settings!$A$7:$B$17,2,FALSE()),1)) | H55: =IF(OR(F57="",G57=""),"",F57/G57) | I55: =IF(B57="","",IFERROR(VLOOKUP(B57,Settings!$E$19:$F$23,2,FALSE()),0)) | J55: =IF(H57="","",IF(OR(B57="Deposit",B57="Cash In"),H57,-(H57/MAX(1-I57,0.0001)))) | K55: =IF(J57="","",IF(ISNUMBER(K56),K56,Settings!$C$4)+J57)
... G298: =IF(E300="","",IFERROR(VLOOKUP(E300,Settings!$A$7:$B$17,2,FALSE()),1)) | H298: =IF(OR(F300="",G300=""),"",F300/G300) | I298: =IF(B300="","",IFERROR(VLOOKUP(B300,Settings!$E$19:$F$23,2,FALSE()),0)) | J298: =IF(H300="","",IF(OR(B300="Deposit",B300="Cash In"),H300,-(H300/MAX(1-I300,0.0001)))) | K298: =IF(J300="","",IF(ISNUMBER(K299),K299,Settings!$C$4)+J300)

Sheet Invoices
A1: 📋 INVOICE TRACKER
A2: All submitted invoices — Status dropdown: ⏳ Pending / ✅ Paid / ⚠ Check / ❓ Clarify
A4: Date Submitted | B4: Invoice # | C4: Payee / Beneficiary | D4: CCY | E4: Inv. Amount | F4: USD Equiv. | G4: Status | H4: Date Paid | I4: Payment Reference | J4: Notes
A5: 11.12.2025 | B5: ASTENO-2025-AS480 | C5: ASTENO LOGISTICS FZCO | D5: AED | E5: 1507500 | F5: =IF(OR(E5="",E5="TBC"),"TBC",IFERROR(E5/VLOOKUP(D5,Settings!$A$7:$B$17,2,FALSE()),E5)) -> 410483.32 | G5: ✅ Paid | H5: 15.12.2025 | I5: MISR-AED-ASTENO | J5: Cash deal + 0.5% fee. Via OILQO SERVICES
A6: 16.12.2025 | B6: Jiaren (unnamed) | C6: POLARIS MARINE LIMITED | D6: CNY | E6: 74520 | F6: =IF(OR(E6="",E6="TBC"),"TBC",IFERROR(E6/VLOOKUP(D6,Settings!$A$7:$B$17,2,FALSE()),E6)) -> 10626.72 | G6: ✅ Paid | H6: 22.12.2025 | I6: PingAn/VESSANG | J6: Jiaren Marine Chem Ron inv
A7: 29.12.2025 | B7: (Solhut TT) | C7: JIANGSU JINYANGTONG SHIPPING | D7: CNY | E7: 381089 | F7: =IF(OR(E7="",E7="TBC"),"TBC",IFERROR(E7/VLOOKUP(D7,Settings!$A$7:$B$17,2,FALSE()),E7)) -> 54344.149 | G7: ✅ Paid | H7: 29.12.2025 | I7: PI9HK3587KA01546 | J7: Solhut HK. Bank of China
A8: 06.01.2026 | B8: SH-TC2401-23 | C8: POLARIS MARINE LIMITED | D8: CNY | E8: 4356737 | F8: =IF(OR(E8="",E8="TBC"),"TBC",IFERROR(E8/VLOOKUP(D8,Settings!$A$7:$B$17,2,FALSE()),E8)) -> 621280.51 | G8: ✅ Paid | H8: 06.01.2026 | I8: 4,356,737.02 CNY.pdf | J8: Chem Ron 23rd hire. USD 696k equiv
A9: 13.01.2026 | B9: 2000166506 | C9: AL WATAN RAK | D9: AED | E9: 30240 | F9: =IF(OR(E9="",E9="TBC"),"TBC",IFERROR(E9/VLOOKUP(D9,Settings!$A$7:$B$17,2,FALSE()),E9)) -> 8234.1729 | G9: ✅ Paid | H9: 14.01.2026 | I9: Ref 1164015 | J9: Inv date 31.12.2025
A10: 13.01.2026 | B10: LUX-INV2025-228 | C10: LUX LIFESTYLES TRADING LLC | D10: AED | E10: 1890 | F10: =IF(OR(E10="",E10="TBC"),"TBC",IFERROR(E10/VLOOKUP(D10,Settings!$A$7:$B$17,2,FALSE()),E10)) -> 514.63581 | G10: ✅ Paid | H10: 14.01.2026 | I10: Ref 1163835 | J10: Event support 01.12.2025
A11: 13.01.2026 | B11: LUX-INV2026-004 | C11: LUX LIFESTYLES TRADING LLC | D11: AED | E11: 27858.6 | F11: =IF(OR(E11="",E11="TBC"),"TBC",IFERROR(E11/VLOOKUP(D11,Settings!$A$7:$B$17,2,FALSE()),E11)) -> 7585.7318 | G11: ✅ Paid | H11: 14.01.2026 | I11: Ref 1163838 | J11: Lutron programming balance
A12: 14.01.2026 | B12: PoF batch Dec 2025 (5 inv) | C12: MENA TERMINALS FUJAIRAH LLC FZC | D12: AED | E12: 283413.37 | F12: =IF(OR(E12="",E12="TBC"),"TBC",IFERROR(E12/VLOOKUP(D12,Settings!$A$7:$B$17,2,FALSE()),E12)) -> 77171.782 | G12: ✅ Paid | H12: 16.01.2026 | I12: Ref 7202386567064989 | J12: 5 invoices. TROVECO payer
A13: 15.01.2026 | B13: 143-122025 | C13: QUILL CORPORATE SERVICES LLC | D13: AED | E13: 9082.5 | F13: =IF(OR(E13="",E13="TBC"),"TBC",IFERROR(E13/VLOOKUP(D13,Settings!$A$7:$B$17,2,FALSE()),E13)) -> 2473.111 | G13: ✅ Paid | H13: 16.01.2026 | I13: Ref 1165703 | J13: M&M DMCC Change of Director
A14: 15.01.2026 | B14: 93-012026 | C14: QUILL CORPORATE SERVICES LLC | D14: AED | E14: 4160 | F14: =IF(OR(E14="",E14="TBC"),"TBC",IFERROR(E14/VLOOKUP(D14,Settings!$A$7:$B$17,2,FALSE()),E14)) -> 1132.7434 | G14: ✅ Paid | H14: 16.01.2026 | I14: Ref 1165881 | J14: Change of Manager & Secretary DMCC
A15: 19.01.2026 | B15: CS/26/01/2480 | C15: RSM STONE FOREST CORPSERVE PTE LTD | D15: SGD | E15: 310.9 | F15: =IF(OR(E15="",E15="TBC"),"TBC",IFERROR(E15/VLOOKUP(D15,Settings!$A$7:$B$17,2,FALSE()),E15)) -> 248.02553 | G15: ✅ Paid | H15: 21.01.2026 | I15: FT26021C826J | J15: MMI — ACRA filing
A16: 19.01.2026 | B16: CS/26/01/2481 | C16: RSM STONE FOREST CORPSERVE PTE LTD | D16: SGD | E16: 310.9 | F16: =IF(OR(E16="",E16="TBC"),"TBC",IFERROR(E16/VLOOKUP(D16,Settings!$A$7:$B$17,2,FALSE()),E16)) -> 248.02553 | G16: ✅ Paid | H16: 21.01.2026 | I16: FT26021C826J | J16: MMR — ACRA filing
... A23: 30.01.2026 | B23: INV-2601-005 | C23: MENURISTIC PTE LTD | D23: USD | E23: 2330 | F23: =IF(OR(E23="",E23="TBC"),"TBC",IFERROR(E23/VLOOKUP(D23,Settings!$A$7:$B$17,2,FALSE()),E23)) -> 2330 | G23: ✅ Paid | H23: 04.02.2026 | I23: FT260346180T | J23: ⚠ Was SGD invoice — agent paid in USD
A24: 10.02.2026 | B24: Inv 39+40+41 (Jul-Sep 25) | C24: A. SHAFRANOV (Rubitron Trade) | D24: USD | E24: 14280.54 | F24: =IF(OR(E24="",E24="TBC"),"TBC",IFERROR(E24/VLOOKUP(D24,Settings!$A$7:$B$17,2,FALSE()),E24)) -> 14280.54 | G24: ⏳ Pending | J24: Agent agreed fiat $14,280.54 on 13.02. NO payment proof in chat. FOLLOW UP!
A25: 11.02.2026 | B25: CS/26/01/1407 | C25: RSM STONE FOREST CORPSERVE PTE LTD | D25: SGD | E25: 1150 | F25: =IF(OR(E25="",E25="TBC"),"TBC",IFERROR(E25/VLOOKUP(D25,Settings!$A$7:$B$17,2,FALSE()),E25)) -> 917.43119 | G25: ✅ Paid | H25: 17.02.2026 | I25: FT26047DC1BF+FT2604752HCH | J25: Myanmar Petroleum Svcs
A26: 11.02.2026 | B26: CS/26/01/1408 | C26: RSM STONE FOREST CORPSERVE PTE LTD | D26: SGD | E26: 776.2 | F26: =IF(OR(E26="",E26="TBC"),"TBC",IFERROR(E26/VLOOKUP(D26,Settings!$A$7:$B$17,2,FALSE()),E26)) -> 619.22617 | G26: ✅ Paid | H26: 17.02.2026 | I26: FT26047DC1BF+FT2604752HCH | J26: MMI
A27: 11.02.2026 | B27: CS/26/01/1409 | C27: RSM STONE FOREST CORPSERVE PTE LTD | D27: SGD | E27: 703.1 | F27: =IF(OR(E27="",E27="TBC"),"TBC",IFERROR(E27/VLOOKUP(D27,Settings!$A$7:$B$17,2,FALSE()),E27)) -> 560.90945 | G27: ✅ Paid | H27: 17.02.2026 | I27: FT26047DC1BF+FT2604752HCH | J27: MMR
A28: 11.02.2026 | B28: CS/26/01/1410 | C28: RSM STONE FOREST CORPSERVE PTE LTD | D28: SGD | E28: 643.1 | F28: =IF(OR(E28="",E28="TBC"),"TBC",IFERROR(E28/VLOOKUP(D28,Settings!$A$7:$B$17,2,FALSE()),E28)) -> 513.04348 | G28: ✅ Paid | H28: 17.02.2026 | I28: FT26047DC1BF+FT2604752HCH | J28: MMT
A29: 11.02.2026 | B29: CS/26/01/1411+1462+1549 | C29: RSM STONE FOREST CORPSERVE PTE LTD | D29: SGD | E29: 2913.05 | F29: =IF(OR(E29="",E29="TBC"),"TBC",IFERROR(E29/VLOOKUP(D29,Settings!$A$7:$B$17,2,FALSE()),E29)) -> 2323.933 | G29: ✅ Paid | H29: 17.02.2026 | I29: FT26047DC1BF+FT2604752HCH | J29: MME+Maritime Shipping+Asia Shipco. Total 7 = 8,596.35 SGD
A30: 11.02.2026 | B30: 014/02/2026 | C30: KINGLET LTD (Cyprus) | D30: EUR | E30: 2800 | F30: =IF(OR(E30="",E30="TBC"),"TBC",IFERROR(E30/VLOOKUP(D30,Settings!$A$7:$B$17,2,FALSE()),E30)) -> 3319.8957 | G30: ✅ Paid | H30: 17.02.2026 | I30: FT26047G4HBJ | J30: KYC/admin Gornik Trading. Nicosia.
A31: 18.02.2026 | B31: 2053_RO | C31: BUSINESS WITHOUT BORDERS LLC | D31: AED | E31: 86520 | F31: =IF(OR(E31="",E31="TBC"),"TBC",IFERROR(E31/VLOOKUP(D31,Settings!$A$7:$B$17,2,FALSE()),E31)) -> 23558.884 | G31: ✅ Paid | H31: 24.02.2026 | I31: FT260556HH32 | J31: HoN RAKEZ L&L renewal 4 companies
A32: 18.02.2026 | B32: 2054_RO | C32: BUSINESS WITHOUT BORDERS LLC | D32: AED | E32: 66412.5 | F32: =IF(OR(E32="",E32="TBC"),"TBC",IFERROR(E32/VLOOKUP(D32,Settings!$A$7:$B$17,2,FALSE()),E32)) -> 18083.73 | G32: ✅ Paid | H32: 24.02.2026 | I32: FT260554C5DC | J32: HoN L&L renewal Al Salaam Solutions
A33: 20.02.2026 | B33: 2075_RO | C33: BUSINESS WITHOUT BORDERS LLC | D33: AED | E33: 13650 | F33: =IF(OR(E33="",E33="TBC"),"TBC",IFERROR(E33/VLOOKUP(D33,Settings!$A$7:$B$17,2,FALSE()),E33)) -> 3716.8142 | G33: ✅ Paid | H33: 24.02.2026 | I33: FT26055VFJC0 | J33: Share transfer IFZA — Muhammed Fazal
A34: 19.02.2026 | B34: DNMUW-487333+562223+563799 | C34: DUBAI INSURANCE COMPANY | D34: AED | E34: 197334.74 | F34: =IF(OR(E34="",E34="TBC"),"TBC",IFERROR(E34/VLOOKUP(D34,Settings!$A$7:$B$17,2,FALSE()),E34)) -> 53733.081 | G34: ⏳ Pending | J34: 3 invoices. Balkemy NOC letter in progress
A35: 19.02.2026 | B35: D-01-25-25172+D-01-26-01144 | C35: ORIENT INSURANCE | D35: AED | E35: 17799.36 | F35: =IF(OR(E35="",E35="TBC"),"TBC",IFERROR(E35/VLOOKUP(D35,Settings!$A$7:$B$17,2,FALSE()),E35)) -> 4846.6603 | G35: ⏳ Pending | J35: 2 invoices. Balkemy NOC letter in progress
A36: 19.02.2026 | B36: FTIV000638 | C36: BERNARD | D36: AED | E36: 14988.6 | F36: =IF(OR(E36="",E36="TBC"),"TBC",IFERROR(E36/VLOOKUP(D36,Settings!$A$7:$B$17,2,FALSE()),E36)) -> 4081.307 | G36: ⏳ Pending
A37: 19.02.2026 | B37: PoF SOA dd 2026-02-09 | C37: MENA TERMINALS FUJAIRAH LLC FZC | D37: AED | E37: 13865.24 | F37: =IF(OR(E37="",E37="TBC"),"TBC",IFERROR(E37/VLOOKUP(D37,Settings!$A$7:$B$17,2,FALSE()),E37)) -> 3775.4227 | G37: ⏳ Pending | J37: NOC letter template sent
A38: 19.02.2026 | B38: inv000347 | C38: FOIZ MENA | D38: AED | E38: 242022.05 | F38: =IF(OR(E38="",E38="TBC"),"TBC",IFERROR(E38/VLOOKUP(D38,Settings!$A$7:$B$17,2,FALSE()),E38)) -> 65901.171 | G38: ⏳ Pending | J38: FOIZ MENA inv000347 — amount from invoice PDF
A39: 19.02.2026 | B39: GL-1589 | C39: AMA GLOBAL AUDITING | D39: USD | E39: 6037.5 | F39: =IF(OR(E39="",E39="TBC"),"TBC",IFERROR(E39/VLOOKUP(D39,Settings!$A$7:$B$17,2,FALSE()),E39)) -> 6037.5 | G39: ⏳ Pending | J39: AMA GLOBAL GL-1589 — amount from invoice PDF
A40: 19.02.2026 | B40: DXL-111843 | C40: GEOCHEM | D40: AED | E40: 8032.5 | F40: =IF(OR(E40="",E40="TBC"),"TBC",IFERROR(E40/VLOOKUP(D40,Settings!$A$7:$B$17,2,FALSE()),E40)) -> 2187.2022 | G40: ⏳ Pending | J40: GEOCHEM DXL-111843 — amount from invoice PDF
A41: 19.02.2026 | B41: 2000170135 | C41: AL WATAN | D41: AED | E41: 30240 | F41: =IF(OR(E41="",E41="TBC"),"TBC",IFERROR(E41/VLOOKUP(D41,Settings!$A$7:$B$17,2,FALSE()),E41)) -> 8234.1729 | G41: ⏳ Pending | J41: AL WATAN 2000170135 — amount from invoice PDF
A42: 24.02.2026 | B42: GP Shipping batch | C42: GOOD PARTNER SHIPPING CO LTD (KR) | D42: USD | E42: 19024.13 | F42: =IF(OR(E42="",E42="TBC"),"TBC",IFERROR(E42/VLOOKUP(D42,Settings!$A$7:$B$17,2,FALSE()),E42)) -> 19024.13 | G42: ⏳ Pending | J42: Kookmin Bank Korea
A43: 23.02.2026 | B43: (TD International) | C43: TD INTERNATIONAL LLC | D43: USD | E43: 200000 | F43: =IF(OR(E43="",E43="TBC"),"TBC",IFERROR(E43/VLOOKUP(D43,Settings!$A$7:$B$17,2,FALSE()),E43)) -> 200000 | G43: ⏳ Pending | J43: Chase Bank CHASUS33. From BALKEMY
A44: 25.02.2026 | B44: INV 4410 (5YZ W L L-2) | C44: 5YZ W.L.L | D44: BHD | E44: 1980 | F44: =IF(OR(E44="",E44="TBC"),"TBC",IFERROR(E44/VLOOKUP(D44,Settings!$A$7:$B$17,2,FALSE()),E44)) -> 5310.3041 | G44: ✅ Paid | H44: 25.02.2026 | J44: Original invoice 1,980 BHD. Agent paid in AED 19,502.10 (see Transactions row 43)
F45: =IF(OR(E45="",E45="TBC"),"TBC",IFERROR(E45/VLOOKUP(D45,Settings!$A$7:$B$17,2,FALSE()),E45)) -> TBC
F46: =IF(OR(E46="",E46="TBC"),"TBC",IFERROR(E46/VLOOKUP(D46,Settings!$A$7:$B$17,2,FALSE()),E46)) -> TBC
F47: =IF(OR(E47="",E47="TBC"),"TBC",IFERROR(E47/VLOOKUP(D47,Settings!$A$7:$B$17,2,FALSE()),E47)) -> TBC
...

Sheet Instructions
A1: 📖 INSTRUCTIONS
A2: How to use this model — read once before you start
A4: OVERVIEW
A5: This model tracks all activity with your financial agent: invoice payments, deposits, cash deliveries, and the running USD balance.
A7: 🗂 SHEETS
A8: 📊 Dashboard | B8: Auto summary — current balance, invoice counts, totals. Nothing to fill in.
A9: 💳 Transactions | B9: Main data entry sheet. Every money movement goes here.
A10: 📋 Invoices | B10: Track every invoice: submitted, pending, paid.
A11: ⚙ Settings | B11: FX rates and commission defaults — update here only.
A13: 🎨 COLOR CODE
A14: 🔵 Blue cells | B14: Your input — type freely here.
A15: 🟡 Yellow cells | B15: Formulas — do NOT type here, they auto-calculate.
A16: 🟢 Green rows | B16: Deposits / paid invoices.
A17: 🟠 Orange rows | B17: Cash Out (agent delivers cash to you).
A18: 🔴 Red rows | B18: Unknown transactions — need clarification.
A20: 📥 ADDING A NEW INVOICE
A21: 1. | B21: Go to 📋 Invoices · scroll to the first empty row.
A22: 2. | B22: Fill in: Date · Invoice # · Payee · Currency · Amount.
A23: 3. | B23: USD Equiv (col F) calculates automatically from Settings rates.
A24: 4. | B24: Set Status dropdown → "⏳ Pending".
A25: 5. | B25: When paid: MUST fill Date Paid (col H) AND Payment Reference (col I) in the SAME operation as changing Status → "✅ Paid". Never leave Date Paid empty if status is Paid.
A27: 💸 ADDING A NEW TRANSACTION
A28: 1. | B28: Go to 💳 Transactions · scroll to the first empty row.
A29: 2. | B29: Fill: Date · Type (dropdown) · Description · Payee · CCY · Amount.
A30: 3. | B30: FX Rate (col G) auto-fills from Settings. Override if agent used a different rate — just type over it.
A31: 4. | B31: Comm % (col I) auto-fills by type. Override if needed (e.g. RUB = 0.4%).
A32: 5. | B32: Gross USD, Net USD, and Balance all calculate automatically.
A34: 🔄 UPDATING FX RATES
A35: → | B35: When agent sends a new balance statement: go to ⚙ Settings, update the blue Rate cells.
A36: → | B36: New transaction rows will pick up the new rate automatically.
A37: → | B37: Historical rows keep their original rate (intentional — matches agent's calculation).
A39: ⚖ RECONCILING AGENT BALANCE STATEMENTS
A40: 1. | B40: Compare agent's ending balance vs 'Current Agent Balance' on Dashboard.
A41: 2. | B41: If different: find transactions in agent's statement not yet in your sheet.
A42: 3. | B42: For anything without a clear invoice: Type = "❓ Unknown". Do NOT delete — ask agent first.
A43: 4. | B43: Small differences (< $500) are usually rounding — note in Notes column.
A45: ⚠ RULES — DO NOT BREAK
A46: RUB commission is 0.4%, not 0.5% | B46: → After adding a RUB row, manually set Comm % (col I) to 0.4%
A47: Do not insert or delete columns | B47: → Formulas rely on column positions. Add/delete ROWS only.
A48: Do not rename sheets | B48: → Formulas reference sheets by name.
...

Sheet Settings
A1: ⚙ SETTINGS
A2: FX rates & commission defaults — update here, all sheets auto-recalculate
A4: STARTING BALANCE (USD) | B4: Enter here → | C4: 0 | D4: ← Balance before the first row in Transactions
A6: FX RATES (1 USD = X) | B6: Rate | C6: Last updated | D6: Source
A7: AED | B7: 3.6725 | C7: 25.12.2025 | D7: Agent balance stmt · stable
A8: CNY | B8: 7.012512 | C8: 13.01.2026 | D8: Agent balance stmt · update each time
A9: USD | B9: 1 | C9: Fixed | D9: Fixed
A10: EUR | B10: 0.8434 | C10: 17.02.2026 | D10: Implied from agent stmt (2,800 EUR = $3,319.78)
A11: SGD | B11: 1.2535 | C11: 21.01.2026 | D11: Cross-rate: 2.93 SGD/AED ÷ 3.6725
A12: RUB | B12: 78.8527 | C12: 14.01.2026 | D12: ЦБ rate · update per agent statement
A13: INR | B13: 90.63 | C13: 17.02.2026 | D13: Implied from agent stmt
A14: HKD | B14: 7.78 | C14: Approx | D14: Market
A15: SAR | B15: 3.75 | C15: Fixed | D15: Fixed peg
A16: GBP | B16: 0.788 | C16: Approx | D16: Market
A17: BHD | B17: 0.37286
A18: TRANSACTION TYPE | B18: Default Comm % | C18: Notes
A19: Deposit | B19: 0 | C19: No fee — we fund the agent
A20: Payment | B20: 0.005 | C20: Standard 0.5%
A21: Cash Out | B21: 0.005 | C21: Standard 0.5% — large deals may differ, override per row
A22: Cash In | B22: 0 | C22: No fee — we send funds to agent
A23: ❓ Unknown | B23: 0 | C23: Set to 0 until clarified
A25: ⚠ TO UPDATE: change blue Rate cells above when agent sends a new balance statement. New Transaction rows will auto-pick up updated rates. Historical rows keep their original rate (intentional).
